<?xml version="1.0" ?>
<!-- =================================================================================== -->
<!-- |    This document was autogenerated by xacro from /home/inoue/catkin_ws/src/urdf_store/urdf/hc10/hc10dt.robot.urdf.xacro | -->
<!-- |    EDITING THIS FILE BY HAND IS NOT RECOMMENDED                                 | -->
<!-- =================================================================================== -->
<robot name="motoman_hc10dt">
    <!-- link list -->
    <link name="base_link">
        <visual>
            <geometry>
                <mesh filename="package://motoman_hc10_support/meshes/hc10/visual/base_link.dae" />
            </geometry>
            <material name="">
                <color rgba="0.12941176470588237 0.14901960784313725 0.7490196078431373 1.0" />
            </material>
        </visual>
        <collision>
            <geometry>
                <mesh filename="package://motoman_hc10_support/meshes/hc10/collision/base_link.stl" />
            </geometry>
        </collision>
        <inertial>
            <mass value="0.1" />
            <origin xyz="0 0 0" rpy="0 0 0" />
            <inertia ixx="0.03" iyy="0.03" izz="0.03" ixy="0.0" ixz="0.0" iyz="0.0" />
        </inertial>
    </link>
    <link name="link_1_s">
        <visual>
            <geometry>
                <mesh filename="package://motoman_hc10_support/meshes/hc10/visual/link_1_s.dae" />
            </geometry>
            <material name="">
                <color rgba="0.12941176470588237 0.14901960784313725 0.7490196078431373 1.0" />
            </material>
        </visual>
        <collision>
            <geometry>
                <mesh filename="package://motoman_hc10_support/meshes/hc10/collision/link_1_s.stl" />
            </geometry>
        </collision>
        <inertial>
            <mass value="0.1" />
            <origin xyz="0 0 0" rpy="0 0 0" />
            <inertia ixx="0.03" iyy="0.03" izz="0.03" ixy="0.0" ixz="0.0" iyz="0.0" />
        </inertial>
    </link>
    <link name="link_2_l">
        <visual>
            <geometry>
                <mesh filename="package://motoman_hc10_support/meshes/hc10/visual/link_2_l.dae" />
            </geometry>
            <material name="">
                <color rgba="0.12941176470588237 0.14901960784313725 0.7490196078431373 1.0" />
            </material>
        </visual>
        <collision>
            <geometry>
                <mesh filename="package://motoman_hc10_support/meshes/hc10/collision/link_2_l.stl" />
            </geometry>
        </collision>
        <inertial>
            <mass value="0.1" />
            <origin xyz="0 0 0" rpy="0 0 0" />
            <inertia ixx="0.03" iyy="0.03" izz="0.03" ixy="0.0" ixz="0.0" iyz="0.0" />
        </inertial>
    </link>
    <link name="link_3_u">
        <visual>
            <geometry>
                <mesh filename="package://motoman_hc10_support/meshes/hc10/visual/link_3_u.dae" />
            </geometry>
            <material name="">
                <color rgba="0.12941176470588237 0.14901960784313725 0.7490196078431373 1.0" />
            </material>
        </visual>
        <collision>
            <geometry>
                <mesh filename="package://motoman_hc10_support/meshes/hc10/collision/link_3_u.stl" />
            </geometry>
        </collision>
        <inertial>
            <mass value="0.1" />
            <origin xyz="0 0 0" rpy="0 0 0" />
            <inertia ixx="0.03" iyy="0.03" izz="0.03" ixy="0.0" ixz="0.0" iyz="0.0" />
        </inertial>
    </link>
    <link name="link_4_r">
        <visual>
            <geometry>
                <mesh filename="package://motoman_hc10_support/meshes/hc10/visual/link_4_r.dae" />
            </geometry>
            <material name="">
                <color rgba="0.12941176470588237 0.14901960784313725 0.7490196078431373 1.0" />
            </material>
        </visual>
        <collision>
            <geometry>
                <mesh filename="package://motoman_hc10_support/meshes/hc10/collision/link_4_r.stl" />
            </geometry>
        </collision>
        <inertial>
            <mass value="0.1" />
            <origin xyz="0 0 0" rpy="0 0 0" />
            <inertia ixx="0.03" iyy="0.03" izz="0.03" ixy="0.0" ixz="0.0" iyz="0.0" />
        </inertial>
    </link>
    <link name="link_5_b">
        <visual>
            <geometry>
                <mesh filename="package://motoman_hc10_support/meshes/hc10/visual/link_5_b.dae" />
            </geometry>
            <material name="">
                <color rgba="0.12941176470588237 0.14901960784313725 0.7490196078431373 1.0" />
            </material>
        </visual>
        <collision>
            <geometry>
                <mesh filename="package://motoman_hc10_support/meshes/hc10/collision/link_5_b.stl" />
            </geometry>
        </collision>
        <inertial>
            <mass value="0.1" />
            <origin xyz="0 0 0" rpy="0 0 0" />
            <inertia ixx="0.03" iyy="0.03" izz="0.03" ixy="0.0" ixz="0.0" iyz="0.0" />
        </inertial>
    </link>
    <link name="link_6_t">
        <visual>
            <geometry>
                <mesh filename="package://motoman_hc10_support/meshes/hc10dt/visual/link_6_t.dae" />
            </geometry>
            <material name="">
                <color rgba="0.12941176470588237 0.14901960784313725 0.7490196078431373 1.0" />
            </material>
        </visual>
        <collision>
            <geometry>
                <mesh filename="package://motoman_hc10_support/meshes/hc10dt/collision/link_6_t.stl" />
            </geometry>
        </collision>
        <inertial>
            <mass value="0.1" />
            <origin xyz="0 0 0" rpy="0 0 0" />
            <inertia ixx="0.03" iyy="0.03" izz="0.03" ixy="0.0" ixz="0.0" iyz="0.0" />
        </inertial>
    </link>
    <link name="tool0" />
    <!-- hand link -->
    <link name="ee_link">
        <visual>
            <geometry>
                <mesh filename="package://urdf_store/urdf/hand/base_hand_pitch_linear_2dof_nozzleguard.stl" />
            </geometry>
            <origin rpy="0.0 0.0 0.0" xyz="0.0 0.0 0.0" />
            <material name="Gray">
                <color rgba="0.5 0.5 0.5 1.0" />
            </material>
        </visual>
        <collision>
            <geometry>
                <mesh filename="package://urdf_store/urdf/hand/base_hand_pitch_linear_2dof_nozzleguard.stl" />
            </geometry>
            <origin rpy="0.0 0.0 0.0" xyz="0.0 0.0 0.0" />
        </collision>
        <inertial>
            <!-- FIXME(PPR): Values for the inertia matrix are dummy and cannot be used!! -->
            <inertia ixx="0.0" ixy="0.0" ixz="0.0" iyy="0.0" iyz="0.0" izz="0.0" />
            <mass value="0.63" />
            <origin rpy="0.0 0.0 0.0" xyz="0.0 0.04 -0.2605" />
        </inertial>
    </link>
    <link name="ee_forcesensor" />
    <!-- end of hand link list -->
    <!-- end of link list -->
    <!-- joint list -->
    <joint name="joint_1_s" type="revolute">
        <parent link="base_link" />
        <child link="link_1_s" />
        <origin rpy="0 0 0" xyz="0 0 0.275" />
        <axis xyz="0 0 1" />
        <limit effort="368.48" lower="-3.141592653589793" upper="3.141592653589793" velocity="2.2689280275926285" />
    </joint>
    <joint name="joint_2_l" type="revolute">
        <parent link="link_1_s" />
        <child link="link_2_l" />
        <origin rpy="0 0 0" xyz="0 0 0" />
        <axis xyz="0 1 0" />
        <limit effort="368.48" lower="-3.141592653589793" upper="3.141592653589793" velocity="2.2689280275926285" />
    </joint>
    <joint name="joint_3_u" type="revolute">
        <parent link="link_2_l" />
        <child link="link_3_u" />
        <origin rpy="0 0 0" xyz="0 0 0.700" />
        <axis xyz="0 -1 0" />
        <limit effort="141.12" lower="-0.08726646259971647" upper="6.19591884457987" velocity="3.141592653589793" />
    </joint>
    <joint name="joint_4_r" type="revolute">
        <parent link="link_3_u" />
        <child link="link_4_r" />
        <origin rpy="0 0 0" xyz="0 0 -0.500" />
        <axis xyz="0 0 1" />
        <limit effort="39.20" lower="-3.141592653589793" upper="3.141592653589793" velocity="3.141592653589793" />
    </joint>
    <joint name="joint_5_b" type="revolute">
        <parent link="link_4_r" />
        <child link="link_5_b" />
        <origin rpy="0 0 0" xyz="0 0.162 0" />
        <axis xyz="0 -1 0" />
        <limit effort="31.36" lower="-3.141592653589793" upper="3.141592653589793" velocity="4.363323129985824" />
    </joint>
    <joint name="joint_6_t" type="revolute">
        <parent link="link_5_b" />
        <child link="link_6_t" />
        <origin rpy="0 0 0" xyz="0 0 0" />
        <axis xyz="0 0 1" />
        <limit effort="31.36" lower="-3.141592653589793" upper="3.141592653589793" velocity="4.363323129985824" />
    </joint>
    <joint name="joint_6_t-tool0" type="fixed">
        <origin rpy="3.141592653589793 0 0" xyz="0 0 -0.170" />
        <parent link="link_6_t" />
        <child link="tool0" />
    </joint>
    <!-- hand joint -->
    <joint name="ee_fixed_joint" type="fixed">
        <parent link="tool0" />
        <child link="ee_link" />
        <origin rpy="0.0 0.0 0.0" xyz="0.0 -0.1 0.2665" />
    </joint>
    <joint name="ee_forcesensor_joint" type="fixed">
        <parent link="tool0" />
        <child link="ee_forcesensor" />
        <origin rpy="0.0 0.0 1.5707963267948966" xyz="0.0 -0.1 0.0573" />
    </joint>
    <!-- end of hand joint list -->
    <!-- end of joint list -->
    <!-- ROS base_link to Robot Manufacturer World Coordinates transform -->
    <link name="base" />
    <joint name="base_link-base" type="fixed">
        <origin rpy="0 0 0" xyz="0 0 0.275" />
        <parent link="base_link" />
        <child link="base" />
    </joint>
    <!-- Base stand-->
    <link name="base_stand_link">
        <visual>
            <origin rpy="0 0 0" xyz="0 0 0" />
            <geometry>
                <!--
          <mesh filename="package://ppr_sandbox_botamochi_sandbox/urdf/stand/2022_Yaskawa_robotbaseorigine_lowpolygon.stl" />
          -->
                <mesh filename="package://urdf_store/urdf/stand/base_and_stand.stl" />
            </geometry>
            <material name="LightGrey">
                <color rgba="0.7 0.7 0.7 1.0" />
            </material>
        </visual>
        <collision>
            <origin rpy="0 0 0" xyz="0 0 0" />
            <geometry>
                <!--
          <mesh filename="package://ppr_sandbox_botamochi_sandbox/urdf/stand/2022_Yaskawa_robotbaseorigine_lowpolygon.stl" />
          -->
                <mesh filename="package://urdf_store/urdf/stand/base_and_stand.stl" />
            </geometry>
        </collision>
        <inertial>
            <mass value="0.1" />
            <origin xyz="0 0 0" rpy="0 0 0" />
            <inertia ixx="0.03" iyy="0.03" izz="0.03" ixy="0.0" ixz="0.0" iyz="0.0" />
        </inertial>
    </link>
    <joint name="base_stand" type="fixed">
        <origin rpy="0 0 0" xyz="0 0 0" />
        <parent link="base_link" />
        <child link="base_stand_link" />
    </joint>
    <link name="world" />
    <joint name="world_joint" type="fixed">
        <parent link="world" />
        <child link="base_link" />
        <origin rpy="0.0 0.0 0.0" xyx="-0.0 0.0 0.0" />
    </joint>
    <tools default="mx35_x1">
        <tool name="pigrip25_x2" rpy="0.0 0.0 0.0" xyz="0.0 0.0 0.045">
            <collision>
                <geometry>
                    <mesh filename="package://urdf_store/urdf/hand/tool/pigrip25_x2.stl" />
                </geometry>
                <origin rpy="0.0 0.0 0.0" xyz="0.0 0.0 0.0" />
            </collision>
            <inertial>
                <inertia ixx="0.0" ixy="0.0" ixz="0.0" iyy="0.0" iyz="0.0" izz="0.0" />
                <mass value="0.025" />
                <origin rpy="0.0 0.0 0.0" xyz="0.0 0.0 0.010" />
            </inertial>
            <effector>
                <suction bellows_length="0.015" diameter="0.025" input_port="0 1" name="default" output_port="0 1" rpy="0.0 0.0 0.0" xyz="0.0 0.0 0.0" />
                <suction bellows_length="0.015" diameter="0.025" input_port="0" name="front" output_port="0" rpy="0.0 0.0 0.0" xyz="0.0 -0.015 0.0" />
                <suction bellows_length="0.015" diameter="0.025" input_port="0" name="back" output_port="1" rpy="0.0 0.0 0.0" xyz="0.0 0.015 0.0" />
                <blow input_port="" name="blow" output_port="4" rpy="0.0 0.0 0.0" xyz="0.0 0.0 0.0" />
                <push bellows_length="0.015" diameter="0.025" input_port="" name="push" output_port="" rpy="0.0 0.0 0.0" xyz="0.0 -0.015 0.0" />
                <push bellows_length="0.015" diameter="0.025" input_port="" name="push_front" output_port="" rpy="0.0 0.0 0.0" xyz="0.0 -0.015 0.0" />
                <push bellows_length="0.015" diameter="0.025" input_port="" name="push_back" output_port="" rpy="0.0 0.0 0.0" xyz="0.0 0.015 0.0" />
            </effector>
        </tool>
        <tool name="mx35_x1" rpy="0.0 0.0 0.0" xyz="0.0 0.0 0.0515">
            <collision>
                <geometry>
                    <mesh filename="package://urdf_store/urdf/hand/tool/mx35_x1.stl" />
                </geometry>
                <origin rpy="0.0 0.0 0.0" xyz="0.0 0.0 0.0" />
            </collision>
            <inertial>
                <inertia ixx="0.0" ixy="0.0" ixz="0.0" iyy="0.0" iyz="0.0" izz="0.0" />
                <mass value="0.037" />
                <origin rpy="0.0 0.0 0.0" xyz="0.0 0.0 0.010" />
            </inertial>
            <effector>
                <suction bellows_length="0.01" diameter="0.035" input_port="0 1" name="default" output_port="0 1" rpy="0.0 0.0 0.0" xyz="0.0 0.0 0.0" />
                <blow input_port="" name="blow" output_port="4" rpy="0.0 0.0 0.0" xyz="0.0 0.0 0.0" />
                <push bellows_length="0.01" diameter="0.035" input_port="" name="push" output_port="" rpy="0.0 0.0 0.0" xyz="0.0 0.0 0.0" />
            </effector>
        </tool>
        <tool name="softgrip" rpy="0.0 0.0 0.0" xyz="0.0 0.0 0.113">
            <collision>
                <geometry>
                    <mesh filename="package://urdf_store/urdf/hand/tool/pisoftgrip_open.stl" />
                </geometry>
                <origin rpy="0.0 0.0 0.0" xyz="0.0 0.0 0.0" />
            </collision>
            <inertial>
                <inertia ixx="0.0" ixy="0.0" ixz="0.0" iyy="0.0" iyz="0.0" izz="0.0" />
                <mass value="0.13" />
                <origin rpy="0.0 0.0 0.0" xyz="0.0 0.0 0.010" />
            </inertial>
            <effector>
                <grasp input_port="" name="default" output_port="0 1" rpy="0.0 0.0 0.0" xyz="0.0 0.0 0.0" />
                <blow input_port="" name="blow" output_port="4" rpy="0.0 0.0 0.0" xyz="0.0 0.0 0.0" />
            </effector>
        </tool>
    </tools>
    <transmission name="trans_joint_1_s">
        <type>transmission_interface/SimpleTransmission</type>
        <joint name="joint_1_s">
            <hardwareInterface>hardware_interface/EffortJointInterface</hardwareInterface>
        </joint>
        <actuator name="joint_1_s_motor">
            <hardwareInterface>hardware_interface/EffortJointInterface</hardwareInterface>
            <mechanicalReduction>1</mechanicalReduction>
        </actuator>
    </transmission>
    <transmission name="trans_joint_2_l">
        <type>transmission_interface/SimpleTransmission</type>
        <joint name="joint_2_l">
            <hardwareInterface>hardware_interface/EffortJointInterface</hardwareInterface>
        </joint>
        <actuator name="joint_2_l_motor">
            <hardwareInterface>hardware_interface/EffortJointInterface</hardwareInterface>
            <mechanicalReduction>1</mechanicalReduction>
        </actuator>
    </transmission>
    <transmission name="trans_joint_3_u">
        <type>transmission_interface/SimpleTransmission</type>
        <joint name="joint_3_u">
            <hardwareInterface>hardware_interface/EffortJointInterface</hardwareInterface>
        </joint>
        <actuator name="joint_3_u_motor">
            <hardwareInterface>hardware_interface/EffortJointInterface</hardwareInterface>
            <mechanicalReduction>1</mechanicalReduction>
        </actuator>
    </transmission>
    <transmission name="trans_joint_4_r">
        <type>transmission_interface/SimpleTransmission</type>
        <joint name="joint_4_r">
            <hardwareInterface>hardware_interface/EffortJointInterface</hardwareInterface>
        </joint>
        <actuator name="joint_4_r_motor">
            <hardwareInterface>hardware_interface/EffortJointInterface</hardwareInterface>
            <mechanicalReduction>1</mechanicalReduction>
        </actuator>
    </transmission>
    <transmission name="trans_joint_5_b">
        <type>transmission_interface/SimpleTransmission</type>
        <joint name="joint_5_b">
            <hardwareInterface>hardware_interface/EffortJointInterface</hardwareInterface>
        </joint>
        <actuator name="joint_5_b_motor">
            <hardwareInterface>hardware_interface/EffortJointInterface</hardwareInterface>
            <mechanicalReduction>1</mechanicalReduction>
        </actuator>
    </transmission>
    <transmission name="trans_joint_6_t">
        <type>transmission_interface/SimpleTransmission</type>
        <joint name="joint_6_t">
            <hardwareInterface>hardware_interface/EffortJointInterface</hardwareInterface>
        </joint>
        <actuator name="joint_6_t_motor">
            <hardwareInterface>hardware_interface/EffortJointInterface</hardwareInterface>
            <mechanicalReduction>1</mechanicalReduction>
        </actuator>
    </transmission>
    <gazebo>
        <plugin name="gazebo_ros_control">
            <robotNamespace>/</robotNamespace>
        </plugin>
    </gazebo>
</robot>

